<?xml version="1.0"?>
<robot name="inverted_pendulum">

  <material name="blue">
    <color rgba="0 0 0.8 1"/>
  </material>
  <material name="black">
    <color rgba="0 0 0 1"/>
  </material>
  <material name="red">
    <color rgba="1 0 0 1"/>
  </material>
  
  <link name="base_link">
    <visual>
      <geometry>
        <cylinder length="0.6" radius="0.2"/>
      </geometry>
      <material name="black"/>
    </visual>
  </link>

  <link name="right_wheel_link">
    <visual>
      <geometry>
        <cylinder length="0.2" radius="0.2"/>
        <origin rpy="0 0 0" xyz="0 0 0"/>
      </geometry>
      <material name="blue"/>
    </visual>
  </link>

<link name="left_wheel_link">
    <visual>
      <geometry>
        <cylinder length="0.2" radius="0.2"/>
        <origin rpy="0 0 0" xyz="0 0 0"/>
        <material name="red"/>
      </geometry>
    </visual>
  </link>

  <joint name="right_wheel_joint" type="continuous">
    <parent link="base_link"/>
    <child link="right_wheel_link"/>
    <axis xyz= "0 0 1"/>
    <origin rpy="0 -1.6 0" xyz="-0.2 0 -0.3"/>
  </joint>

   <joint name="left_wheel_joint" type="continuous">
    <parent link="base_link"/>
    <child link="left_wheel_link"/>
    <axis xyz= "0 0 1"/>
    <origin rpy="0 1.6 0" xyz="0.2 0 -0.3"/>
  </joint>
</robot>